Workbook

Sheet Movimentações
C1: OBRA - BRT AUGUSTO MONTENEGRO
C2: CONTROLE DE ESTOQUE
A3: Data de Movimentação | B3: NF/REQ. | C3: Material | D3: Tipo de Movimentação | E3: Quantidade | F3: Custo Unitário (R$) | G3: Custo Total (R$) | H3: TIPO
A4: 46273 | B4: SALDO | C4: PASTA SUSPENSA | D4: Entrada | E4: 69
A5: 46273 | B5: SALDO | C5: PICARETA | D5: Entrada | E5: 2 | H5: FERRAMENTAS
A6: 46273 | B6: SALDO | C6: ELETRODUTO CORRUGADO 2 POL | D6: Entrada | E6: 150
A7: 46273 | B7: SALDO | C7: GARRAFA TERMICA 5L | D7: Entrada | E7: 4 | H7: DIVERSOS
A8: 46273 | B8: SALDO | C8: ELETRODUTO CORRUGADO 2 POL | D8: Entrada | E8: 200
A9: 46273 | B9: SALDO | C9: ALCOOL EM GEL 900ML | D9: Entrada | E9: 4
A10: 46273 | B10: SALDO | C10: FORMULÁRIO DE REQUISIÇÃO INTERNA | D10: Entrada | E10: 1
A11: 46273 | B11: SALDO
A12: 46273 | B12: SALDO
A13: 46273 | B13: SALDO
A14: 46279 | B14: 28390 | C14: SACO DE LIXO 30LT | D14: Entrada | E14: 10 | F14: 2.16 | G14: =IF(OR(E14="",F14=""),"",E14*F14) -> 21.6
A15: 46279 | B15: 28390 | C15: PAPEL HIGIÊNICO | D15: Entrada | E15: 1 | F15: 4.34 | G15: =IF(OR(E15="",F15=""),"",E15*F15) -> 4.34
A16: 46279 | B16: 28390 | C16: ÁGUA SANITÁRIA | D16: Entrada | E16: 5 | F16: 2.35 | G16: =IF(OR(E16="",F16=""),"",E16*F16) -> 11.75
A17: 46279 | B17: 28390 | C17: DETERGENTE LÍQUIDO | D17: Entrada | E17: 10 | F17: 2.42 | G17: =IF(OR(E17="",F17=""),"",E17*F17) -> 24.2
A18: 46279 | B18: 28390 | C18: ESPONJA DUPLA FACE | D18: Entrada | E18: 10 | F18: 0.95 | G18: =IF(OR(E18="",F18=""),"",E18*F18) -> 9.5
A19: 46279 | B19: 28390 | C19: COPO DESCARTÁVEL | D19: Entrada | E19: 25 | F19: 6.51 | G19: =IF(OR(E19="",F19=""),"",E19*F19) -> 162.75
A20: 46279 | B20: 28390 | C20: PANO DE CHÃO | D20: Entrada | E20: 5 | F20: 2.98 | G20: =IF(OR(E20="",F20=""),"",E20*F20) -> 14.9
A21: 46279 | B21: 28390 | C21: ENVELOPE TIPO A4 | D21: Entrada | E21: 10 | F21: 0.48 | G21: =IF(OR(E21="",F21=""),"",E21*F21) -> 4.8
A22: 46279 | B22: 28390 | C22: PASTA SANFONADA | D22: Entrada | E22: 2 | F22: 53.91 | G22: =IF(OR(E22="",F22=""),"",E22*F22) -> 107.82
A23: 46279 | B23: 28390 | C23: PAPEL A4 | D23: Entrada | E23: 4 | F23: 27.16 | G23: =IF(OR(E23="",F23=""),"",E23*F23) -> 108.64
A24: 46279 | B24: 28390 | C24: CANETA ESFEROGRÁFICA | D24: Entrada | E24: 10 | F24: 0.9 | G24: =IF(OR(E24="",F24=""),"",E24*F24) -> 9
A25: 46279 | B25: 28390 | C25: REGUA 30 CM | D25: Entrada | E25: 4 | F25: 1.11 | G25: =IF(OR(E25="",F25=""),"",E25*F25) -> 4.44
... A32: 38977 | B32: 28416 | C32: PAPEL TOALHA FOLHEADO | D32: Entrada | E32: 1 | F32: 6.18 | G32: =IF(OR(E32="",F32=""),"",E32*F32) -> 6.18
A33: 46286 | B33: 28430 | C33: ÁGUA MINERAL - 20L | D33: Entrada | E33: 4 | F33: 7.5 | G33: =IF(OR(E33="",F33=""),"",E33*F33) -> 30
A34: 46286 | B34: 28430 | C34: LUVA DE MALHA PIG PRETA - EPI/EPC | D34: Entrada | E34: 48 | F34: 2.07 | G34: =IF(OR(E34="",F34=""),"",E34*F34) -> 99.36
A35: 46286 | B35: 28429 | C35: LIVRO DE PROTOCOLO | D35: Entrada | E35: 1 | F35: 10.46 | G35: =IF(OR(E35="",F35=""),"",E35*F35) -> 10.46
A36: 46286 | B36: 28429 | C36: FORMULÁRIO DE REQUISIÇÃO INTERNA | D36: Entrada | E36: 1 | F36: 12 | G36: =IF(OR(E36="",F36=""),"",E36*F36) -> 12
A37: 46286 | B37: 28429 | C37: CANETA ESFEROGRÁFICA | D37: Entrada | E37: 5 | F37: 0.84 | G37: =IF(OR(E37="",F37=""),"",E37*F37) -> 4.2
A38: 46286 | B38: 28429 | C38: GRAMPEADOR | D38: Entrada | E38: 1 | F38: 14.65 | G38: =IF(OR(E38="",F38=""),"",E38*F38) -> 14.65
A39: 46286 | B39: 28429 | C39: GRAMPO PARA GRAMPEADOR | D39: Entrada | E39: 2 | F39: 4.23 | G39: =IF(OR(E39="",F39=""),"",E39*F39) -> 8.46
A40: 46286 | B40: 28429 | C40: CLIPS 3/0 | D40: Entrada | E40: 3 | F40: 2.34 | G40: =IF(OR(E40="",F40=""),"",E40*F40) -> 7.02
A41: 46286 | B41: 28429 | C41: ALMOFADA PARA CARIMBO | D41: Entrada | E41: 1 | F41: 4.12 | G41: =IF(OR(E41="",F41=""),"",E41*F41) -> 4.12
A42: 46286 | B42: 28429 | C42: ESTILETE GRANDE | D42: Entrada | E42: 1 | F42: 1.4 | G42: =IF(OR(E42="",F42=""),"",E42*F42) -> 1.4
A43: 46286 | B43: 28429 | C43: EXTRATOR DE GRAMPO | D43: Entrada | E43: 2 | F43: 1.72 | G43: =IF(OR(E43="",F43=""),"",E43*F43) -> 3.44
A44: 46281 | B44: 28402 | C44: MEIO FIO SLD 45 X 30 X 10 | D44: Entrada | E44: 400 | F44: 30.96 | G44: =IF(OR(E44="",F44=""),"",E44*F44) -> 12384
A45: 46282 | B45: 28410 | C45: CIMENTO POTY 50KG | D45: Entrada | E45: 80 | F45: 50.04 | G45: =IF(OR(E45="",F45=""),"",E45*F45) -> 4003.2
A46: 46220 | B46: 28411 | C46: ELETRODUTO CORRUGADO 4 POL | D46: Entrada | E46: 250 | F46: 16.68 | G46: =IF(OR(E46="",F46=""),"",E46*F46) -> 4170
...

Sheet Resumo de Estoque
B1: OBRA - BRT AUGUSTO MONTENEGRO
B2: SALDO DE ESTOQUE | F2: =SUM(F4:F103) -> 89309.69
A3: MATERIAL | B3: Total de Entradas | C3: Total de Saídas | D3: Saldo em Estoque | E3: Valor Médio Unitário (R$) | F3: Valor em Estoque (R$)
A4: ALMOFADA PARA CARIMBO | B4: =IF(A4="","",SUMIFS(Movimentações!$E$4:$E$461,Movimentações!$C$4:$C$461,A4,Movimentações!$D$4:$D$461,"Entrada")) -> 4 | C4: =IF(A4="","",SUMIFS(Movimentações!$E$4:$E$461,Movimentações!$C$4:$C$461,A4,Movimentações!$D$4:$D$461,"Saída")) -> 3 | D4: =IF(A4="","",B4-C4) -> 1 | E4: =IF(A4="","",IFERROR(SUMIFS(Movimentações!$G$4:$G$461,Movimentações!$C$4:$C$461,A4,Movimentações!$D$4:$D$461,"Entrada")/B4,0)) -> 4.12 | F4: =IF(A4="","",D4*E4) -> 4.12
A5: BLOCO ESTRUTURAL 09 X 19 X 39 | B5: =IF(A5="","",SUMIFS(Movimentações!$E$4:$E$461,Movimentações!$C$4:$C$461,A5,Movimentações!$D$4:$D$461,"Entrada")) -> 750 | C5: =IF(A5="","",SUMIFS(Movimentações!$E$4:$E$461,Movimentações!$C$4:$C$461,A5,Movimentações!$D$4:$D$461,"Saída")) -> 300 | D5: =IF(A5="","",B5-C5) -> 450 | E5: =IF(A5="","",IFERROR(SUMIFS(Movimentações!$G$4:$G$461,Movimentações!$C$4:$C$461,A5,Movimentações!$D$4:$D$461,"Entrada")/B5,0)) -> 6.45 | F5: =IF(A5="","",D5*E5) -> 2902.5
A6: CANETA ESFEROGRÁFICA | B6: =IF(A6="","",SUMIFS(Movimentações!$E$4:$E$461,Movimentações!$C$4:$C$461,A6,Movimentações!$D$4:$D$461,"Entrada")) -> 65 | C6: =IF(A6="","",SUMIFS(Movimentações!$E$4:$E$461,Movimentações!$C$4:$C$461,A6,Movimentações!$D$4:$D$461,"Saída")) -> 22 | D6: =IF(A6="","",B6-C6) -> 43 | E6: =IF(A6="","",IFERROR(SUMIFS(Movimentações!$G$4:$G$461,Movimentações!$C$4:$C$461,A6,Movimentações!$D$4:$D$461,"Entrada")/B6,0)) -> 0.88 | F6: =IF(A6="","",D6*E6) -> 37.84
A7: CIMENTO POTY 50KG | B7: =IF(A7="","",SUMIFS(Movimentações!$E$4:$E$461,Movimentações!$C$4:$C$461,A7,Movimentações!$D$4:$D$461,"Entrada")) -> 80 | C7: =IF(A7="","",SUMIFS(Movimentações!$E$4:$E$461,Movimentações!$C$4:$C$461,A7,Movimentações!$D$4:$D$461,"Saída")) -> 13 | D7: =IF(A7="","",B7-C7) -> 67 | E7: =IF(A7="","",IFERROR(SUMIFS(Movimentações!$G$4:$G$461,Movimentações!$C$4:$C$461,A7,Movimentações!$D$4:$D$461,"Entrada")/B7,0)) -> 50.04 | F7: =IF(A7="","",D7*E7) -> 3352.68
A8: CLIPS 3/0 | B8: =IF(A8="","",SUMIFS(Movimentações!$E$4:$E$461,Movimentações!$C$4:$C$461,A8,Movimentações!$D$4:$D$461,"Entrada")) -> 3 | C8: =IF(A8="","",SUMIFS(Movimentações!$E$4:$E$461,Movimentações!$C$4:$C$461,A8,Movimentações!$D$4:$D$461,"Saída")) -> 3 | D8: =IF(A8="","",B8-C8) -> 0 | E8: =IF(A8="","",IFERROR(SUMIFS(Movimentações!$G$4:$G$461,Movimentações!$C$4:$C$461,A8,Movimentações!$D$4:$D$461,"Entrada")/B8,0)) -> 2.34 | F8: =IF(A8="","",D8*E8) -> 0
A9: CLIPS 4/0 | B9: =IF(A9="","",SUMIFS(Movimentações!$E$4:$E$461,Movimentações!$C$4:$C$461,A9,Movimentações!$D$4:$D$461,"Entrada")) -> 16 | C9: =IF(A9="","",SUMIFS(Movimentações!$E$4:$E$461,Movimentações!$C$4:$C$461,A9,Movimentações!$D$4:$D$461,"Saída")) -> 7 | D9: =IF(A9="","",B9-C9) -> 9 | E9: =IF(A9="","",IFERROR(SUMIFS(Movimentações!$G$4:$G$461,Movimentações!$C$4:$C$461,A9,Movimentações!$D$4:$D$461,"Entrada")/B9,0)) -> 2.341875 | F9: =IF(A9="","",D9*E9) -> 21.076875
A10: CLIPS 6/0 | B10: =IF(A10="","",SUMIFS(Movimentações!$E$4:$E$461,Movimentações!$C$4:$C$461,A10,Movimentações!$D$4:$D$461,"Entrada")) -> 2 | C10: =IF(A10="","",SUMIFS(Movimentações!$E$4:$E$461,Movimentações!$C$4:$C$461,A10,Movimentações!$D$4:$D$461,"Saída")) -> 2 | D10: =IF(A10="","",B10-C10) -> 0 | E10: =IF(A10="","",IFERROR(SUMIFS(Movimentações!$G$4:$G$461,Movimentações!$C$4:$C$461,A10,Movimentações!$D$4:$D$461,"Entrada")/B10,0)) -> 2.15 | F10: =IF(A10="","",D10*E10) -> 0
A11: COPO DESCARTÁVEL | B11: =IF(A11="","",SUMIFS(Movimentações!$E$4:$E$461,Movimentações!$C$4:$C$461,A11,Movimentações!$D$4:$D$461,"Entrada")) -> 75 | C11: =IF(A11="","",SUMIFS(Movimentações!$E$4:$E$461,Movimentações!$C$4:$C$461,A11,Movimentações!$D$4:$D$461,"Saída")) -> 27 | D11: =IF(A11="","",B11-C11) -> 48 | E11: =IF(A11="","",IFERROR(SUMIFS(Movimentações!$G$4:$G$461,Movimentações!$C$4:$C$461,A11,Movimentações!$D$4:$D$461,"Entrada")/B11,0)) -> 5.2366667 | F11: =IF(A11="","",D11*E11) -> 251.36
A12: DETERGENTE LÍQUIDO | B12: =IF(A12="","",SUMIFS(Movimentações!$E$4:$E$461,Movimentações!$C$4:$C$461,A12,Movimentações!$D$4:$D$461,"Entrada")) -> 10 | C12: =IF(A12="","",SUMIFS(Movimentações!$E$4:$E$461,Movimentações!$C$4:$C$461,A12,Movimentações!$D$4:$D$461,"Saída")) -> 3 | D12: =IF(A12="","",B12-C12) -> 7 | E12: =IF(A12="","",IFERROR(SUMIFS(Movimentações!$G$4:$G$461,Movimentações!$C$4:$C$461,A12,Movimentações!$D$4:$D$461,"Entrada")/B12,0)) -> 2.42 | F12: =IF(A12="","",D12*E12) -> 16.94
A13: ELETRODUTO CORRUGADO 4 POL | B13: =IF(A13="","",SUMIFS(Movimentações!$E$4:$E$461,Movimentações!$C$4:$C$461,A13,Movimentações!$D$4:$D$461,"Entrada")) -> 750 | C13: =IF(A13="","",SUMIFS(Movimentações!$E$4:$E$461,Movimentações!$C$4:$C$461,A13,Movimentações!$D$4:$D$461,"Saída")) -> 50 | D13: =IF(A13="","",B13-C13) -> 700 | E13: =IF(A13="","",IFERROR(SUMIFS(Movimentações!$G$4:$G$461,Movimentações!$C$4:$C$461,A13,Movimentações!$D$4:$D$461,"Entrada")/B13,0)) -> 16.68 | F13: =IF(A13="","",D13*E13) -> 11676
A14: ENVELOPE TIPO A4 | B14: =IF(A14="","",SUMIFS(Movimentações!$E$4:$E$461,Movimentações!$C$4:$C$461,A14,Movimentações!$D$4:$D$461,"Entrada")) -> 20 | C14: =IF(A14="","",SUMIFS(Movimentações!$E$4:$E$461,Movimentações!$C$4:$C$461,A14,Movimentações!$D$4:$D$461,"Saída")) -> 20 | D14: =IF(A14="","",B14-C14) -> 0 | E14: =IF(A14="","",IFERROR(SUMIFS(Movimentações!$G$4:$G$461,Movimentações!$C$4:$C$461,A14,Movimentações!$D$4:$D$461,"Entrada")/B14,0)) -> 0.48 | F14: =IF(A14="","",D14*E14) -> 0
A15: ESPONJA DUPLA FACE | B15: =IF(A15="","",SUMIFS(Movimentações!$E$4:$E$461,Movimentações!$C$4:$C$461,A15,Movimentações!$D$4:$D$461,"Entrada")) -> 10 | C15: =IF(A15="","",SUMIFS(Movimentações!$E$4:$E$461,Movimentações!$C$4:$C$461,A15,Movimentações!$D$4:$D$461,"Saída")) -> 5 | D15: =IF(A15="","",B15-C15) -> 5 | E15: =IF(A15="","",IFERROR(SUMIFS(Movimentações!$G$4:$G$461,Movimentações!$C$4:$C$461,A15,Movimentações!$D$4:$D$461,"Entrada")/B15,0)) -> 0.95 | F15: =IF(A15="","",D15*E15) -> 4.75
... A96: Total Geral | B96: =IF(A96="","",SUMIFS(Movimentações!$E$4:$E$461,Movimentações!$C$4:$C$461,A96,Movimentações!$D$4:$D$461,"Entrada")) -> 0 | C96: =IF(A96="","",SUMIFS(Movimentações!$E$4:$E$461,Movimentações!$C$4:$C$461,A96,Movimentações!$D$4:$D$461,"Saída")) -> 0 | D96: =IF(A96="","",B96-C96) -> 0 | E96: =IF(A96="","",IFERROR(SUMIFS(Movimentações!$G$4:$G$461,Movimentações!$C$4:$C$461,A96,Movimentações!$D$4:$D$461,"Entrada")/B96,0)) -> 0 | F96: =IF(A96="","",D96*E96) -> 0
B97: =IF(A97="","",SUMIFS(Movimentações!$E$4:$E$461,Movimentações!$C$4:$C$461,A97,Movimentações!$D$4:$D$461,"Entrada")) | C97: =IF(A97="","",SUMIFS(Movimentações!$E$4:$E$461,Movimentações!$C$4:$C$461,A97,Movimentações!$D$4:$D$461,"Saída")) | D97: =IF(A97="","",B97-C97) | E97: =IF(A97="","",IFERROR(SUMIFS(Movimentações!$G$4:$G$461,Movimentações!$C$4:$C$461,A97,Movimentações!$D$4:$D$461,"Entrada")/B97,0)) | F97: =IF(A97="","",D97*E97)
B98: =IF(A98="","",SUMIFS(Movimentações!$E$4:$E$461,Movimentações!$C$4:$C$461,A98,Movimentações!$D$4:$D$461,"Entrada")) | C98: =IF(A98="","",SUMIFS(Movimentações!$E$4:$E$461,Movimentações!$C$4:$C$461,A98,Movimentações!$D$4:$D$461,"Saída")) | D98: =IF(A98="","",B98-C98) | E98: =IF(A98="","",IFERROR(SUMIFS(Movimentações!$G$4:$G$461,Movimentações!$C$4:$C$461,A98,Movimentações!$D$4:$D$461,"Entrada")/B98,0)) | F98: =IF(A98="","",D98*E98)
B99: =IF(A99="","",SUMIFS(Movimentações!$E$4:$E$461,Movimentações!$C$4:$C$461,A99,Movimentações!$D$4:$D$461,"Entrada")) | C99: =IF(A99="","",SUMIFS(Movimentações!$E$4:$E$461,Movimentações!$C$4:$C$461,A99,Movimentações!$D$4:$D$461,"Saída")) | D99: =IF(A99="","",B99-C99) | E99: =IF(A99="","",IFERROR(SUMIFS(Movimentações!$G$4:$G$461,Movimentações!$C$4:$C$461,A99,Movimentações!$D$4:$D$461,"Entrada")/B99,0)) | F99: =IF(A99="","",D99*E99)
B100: =IF(A100="","",SUMIFS(Movimentações!$E$4:$E$461,Movimentações!$C$4:$C$461,A100,Movimentações!$D$4:$D$461,"Entrada")) | C100: =IF(A100="","",SUMIFS(Movimentações!$E$4:$E$461,Movimentações!$C$4:$C$461,A100,Movimentações!$D$4:$D$461,"Saída")) | D100: =IF(A100="","",B100-C100) | E100: =IF(A100="","",IFERROR(SUMIFS(Movimentações!$G$4:$G$461,Movimentações!$C$4:$C$461,A100,Movimentações!$D$4:$D$461,"Entrada")/B100,0)) | F100: =IF(A100="","",D100*E100)
B101: =IF(A101="","",SUMIFS(Movimentações!$E$4:$E$461,Movimentações!$C$4:$C$461,A101,Movimentações!$D$4:$D$461,"Entrada")) | C101: =IF(A101="","",SUMIFS(Movimentações!$E$4:$E$461,Movimentações!$C$4:$C$461,A101,Movimentações!$D$4:$D$461,"Saída")) | D101: =IF(A101="","",B101-C101) | E101: =IF(A101="","",IFERROR(SUMIFS(Movimentações!$G$4:$G$461,Movimentações!$C$4:$C$461,A101,Movimentações!$D$4:$D$461,"Entrada")/B101,0)) | F101: =IF(A101="","",D101*E101)

Sheet Inventário
A3: MATERIAL | B3: Saldo em Sistema | C3: Físico | D3: Diferença
A4: AGUA MINERAL - 20LI | B4: 4 | C4: 0 | D4: =B4-C4 -> 4
A5: AGUA SANITÁRIA | B5: 5 | C5: 3 | D5: =B5-C5 -> 2
A6: ALMOFADA PARA CARIMBO | B6: 1 | C6: 1 | D6: =B6-C6 -> 0
A7: BLOCO ESTRUTURAL 09 X 19 X 39 | B7: 750 | C7: 600 | D7: =B7-C7 -> 150
A8: CANETA ESFEROGRÁFICA | B8: 15 | C8: 0 | D8: =B8-C8 -> 15
A9: CIMENTO POTY 50KG | B9: 80 | C9: 77 | D9: =B9-C9 -> 3
A10: CLIPS 3/0 | B10: 3 | C10: 0 | D10: =B10-C10 -> 3
A11: CLIPS 4/0 | B11: 3 | C11: 0 | D11: =B11-C11 -> 3
A12: CLIPS 6/0 | B12: 2 | C12: 0 | D12: =B12-C12 -> 2
A13: COPO DESCARTÁVEL | B13: 25 | C13: 9 | D13: =B13-C13 -> 16
A14: DETERGENTE LÍQUIDO | B14: 10 | C14: 8 | D14: =B14-C14 -> 2
A15: ELETRODUTO CORRUGADO 4 POL | B15: 250 | C15: 250 | D15: =B15-C15 -> 0
... A59: DESEMPENADEIRA | B59: 4 | C59: 4 | D59: =B59-C59 -> 0
